<?xml version="1.0"?>
<robot xmlns:xacro="http://www.ros.org/wiki/xacro">

    <xacro:include filename ="inertial_macros.xacro"/>
    <xacro:property name="robot_name" value="$(arg namespace)"/>

    <material name = "white">
        <color rgba ="1 1 1 1"/>
    </material>

    <material name = "orange">
        <color rgba ="1 0.3 0.1 1"/>
    </material>

    <material name = "blue">
        <color rgba ="0.2 0.2 1 1"/>
    </material>

    <material name = "black">
        <color rgba ="0 0 0 1"/>
    </material>

    <material name = "red">
        <color rgba ="1 0 0 1"/>
    </material>



    <!-- BASE FOOTPRINT LINK-->
    <link name="${robot_name}/base_footprint">
    </link>

    <link name ="${robot_name}/base_link">
    </link>

    <!-- BASE LINK-->
    <joint name ="${robot_name}/base_joint" type ="fixed">
        <parent link ="${robot_name}/base_footprint"/>
        <child link ="${robot_name}/base_link"/>
        <origin xyz = "0 0 0.05" rpy = "0 0 0"/>
    </joint>



    <!--CHASSIS LINK-->

    <link name ="${robot_name}/chassis">
        <visual>
            <origin xyz ="0.15 0 0.075"/>
            <geometry>
                <box size = "0.3 0.3 0.15"/>
            </geometry>
            <material name ="white"/>
        </visual>
        <collision>
            <origin xyz ="0.15 0 0.075"/>
            <geometry>
                <box size = "0.3 0.3 0.15"/>
            </geometry>
        </collision>
        <xacro:inertial_box mass = "0.5" x ="0.3" y="0.3" z="0.15">
            <origin xyz="0.15 0 0.075" rpy = "0 0 0"/>
        </xacro:inertial_box>
            
    </link>

    <joint name="${robot_name}/chassis_joint" type ="fixed">
        <parent link ="${robot_name}/base_link"/>
        <child link = "${robot_name}/chassis"/>
        <origin xyz="-0.1 0 0"/>

    </joint>



    <gazebo reference = "${robot_name}/chassis">
        <material>Gazebo/White</material>
    </gazebo>

    <!-- LEFT WHEEL LINK-->
    <link name ="${robot_name}/left_wheel">
        <visual>
            <geometry>
                <cylinder radius = "0.05" length ="0.04"/>
            </geometry>
            <material name="blue"/>
        </visual>
        <collision>
            <geometry>
                <cylinder radius = "0.05" length ="0.04"/>
            </geometry>
        </collision>
        <xacro:inertial_cylinder mass = "0.1" length ="0.04" radius="0.05">
            <origin xyz="0 0 0" rpy = "0 0 0"/>
        </xacro:inertial_cylinder>
    </link>

    <joint name = "${robot_name}/left_wheel_joint" type = "continuous">
        <parent link = "${robot_name}/base_link"/>
        <child link ="${robot_name}/left_wheel"/>
        <origin xyz = "0 0.175 0" rpy ="-${pi/2} 0 0"/>
        <axis xyz = " 0 0 1"/>
    </joint>

    <gazebo reference = "${robot_name}/left_wheel">
        <material>Gazebo/Blue</material>
    </gazebo>

        <!-- RIGHT WHEEL LINK-->

    <link name ="${robot_name}/right_wheel">
        <visual>
            <geometry>
                <cylinder radius = "0.05" length ="0.04"/>
            </geometry>
            <material name="blue"/>
        </visual>
        <collision>
            <geometry>
                <cylinder radius = "0.05" length ="0.04"/>
            </geometry>
        </collision>
        <xacro:inertial_cylinder mass = "0.1" length ="0.04" radius="0.05">
            <origin xyz="0 0 0" rpy = "0 0 0"/>
        </xacro:inertial_cylinder>
    </link>

    <joint name = "${robot_name}/right_wheel_joint" type = "continuous">
        <parent link = "${robot_name}/base_link"/>
        <child link ="${robot_name}/right_wheel"/>
        <origin xyz = "0 -0.175 0" rpy ="${pi/2} 0 0"/>
        <axis xyz = " 0 0 -1"/>
    </joint>


    <gazebo reference = "${robot_name}/right_wheel">
        <material>Gazebo/Blue</material>
    </gazebo>


    <!--CASTER WHEEL LINK-->

    <link name ="${robot_name}/caster_wheel">
        <visual>
            <geometry>
                <sphere radius="0.05"/>
            </geometry>
            <material name ="black"/>
        </visual>
        <collision>
            <geometry>
                <sphere radius="0.05"/>
            </geometry>
        </collision>
        <xacro:inertial_sphere mass = "0.1" radius="0.05">
            <origin xyz="0 0 0" rpy = "0 0 0"/>
        </xacro:inertial_sphere>
    </link>

    <joint name ="${robot_name}/caster_wheel_joint" type="fixed">
        <parent link = "${robot_name}/chassis"/>
        <child link = "${robot_name}/caster_wheel"/>
        <origin xyz = "0.24 0 0"/>
    </joint>
       
    <gazebo reference = "${robot_name}/caster_wheel">
        <material>Gazebo/Black</material>
        <mu1 value ="0.003"/>
        <mu2 value ="0.003"/>
    </gazebo>

</robot>
